Workbook

Sheet GİRİŞ
A1: ED | B1: VERİ BAŞLIKLARI | C1: GEMİ BİLGİLERİ DOLDUR
B4: GEMİ ADI : | C4: M/T ALSU
B5: NRT (Net Tonaj) : | C5: 1004
B6: GRT (Gross Tonaj) : | C6: 2298
B7: YÜK MİKTARI : | C7: 3001
B8: BARINMA SÜRESİ : | C8: 4
B9: ÖN GÖRÜLEN DEMİRLEME SÜRESİ :
B10: TEHLİKELİ YÜK : | C10: EVET
B11: GÜMRÜK SEÇ : | C11: İTHALAT
B13: DTO: | C13: TÜRK / CHAMBER OF SHIPPING FEE
B14: BARINMA / LİMAN : | C14: YABANCI
B16: FENER: | C16: TÜRK
B18: VTS: | C18: TÜRK
B20: REF NO : | C20: 2026/1202
B22: TO KISMI : | C22: CHEMTANKERS SHIPPING SA
B23: BAYRAK: | C23: TURKIYE
B24: GELİŞ NEDENİ: | C24: Discharging
B25: KARGO CİNSİ : | C25: SFS OIL
B26: LİMAN: | C26: IZMIR
B27: OTO SERVİS

Sheet TUPRAS
B1: ="PROFORMA D/A – INVOICE (Ref: " & 'GİRİŞ'!C20 & " - " & 'GİRİŞ'!C4 & " Call at " & 'GİRİŞ'!C26 & ")" -> PROFORMA D/A – INVOICE (Ref: 2026/1202 - M/T ALSU Call at IZMIR)
A4: ="TO: " & 'GİRİŞ'!C22 -> TO: CHEMTANKERS SHIPPING SA
A5: ="DATE: " & TEXT('SARI YERLERI DOLDUR'!B1, "dd.mm.yyyy") -> DATE: 24.02.2026
A8: Vessel's Particulars | E8: Port: | F8: ALIAGA
A9: Name Of Vsl: | B9: ='SARI YERLERI DOLDUR'!B7 -> M/T ALSU | E9: Purpose Of Call: | F9: ='SARI YERLERI DOLDUR'!E8 -> Discharging
A10: Flag : | B10: ='SARI YERLERI DOLDUR'!E2 -> TURKIYE | E10: Kind Of Cargo: | F10: ='SARI YERLERI DOLDUR'!E9 -> SFS OIL
A11: Nrt: | B11: ='SARI YERLERI DOLDUR'!B8 -> 1004 | E11: Qnty Of Cargo: | F11: ='SARI YERLERI DOLDUR'!B10 -> 3001
A12: Grt: | B12: ='SARI YERLERI DOLDUR'!B9 -> 2298 | E12: Est. Berth Stay: | F12: ='SARI YERLERI DOLDUR'!B11 -> 4
A15: $ 1 = | B15: ='SARI YERLERI DOLDUR'!B6 -> 1.178495 | C15: TUPRAS port in Turkey in/out exp.(estimated)
A16: ='SARI YERLERI DOLDUR'!B24 -> 958.386 | B16: =A16/B15 -> 813.22874 | C16: Pilotage (%50 overtime will applicable on National/ Religions holidays & sundays)
A17: ='SARI YERLERI DOLDUR'!B25 -> 1369.498 | B17: =A17/B15 -> 1162.0737 | C17: Tugboats (%50 overtime will applicable on National/ Religions holidays & sundays)
A18: ='SARI YERLERI DOLDUR'!B32 -> 300 | B18: =A18/B15 -> 254.56196 | C18: Wharfage / Quay dues
A19: ='SARI YERLERI DOLDUR'!B26 -> 117.416 | B19: =A19/B15 -> 99.632158 | C19: Mooring boat (%50 overtime will applicable on National/ Religions holidays & sundays)
A20: ='SARI YERLERI DOLDUR'!B14 -> 164.9893 | B20: =A20/B15 -> 140 | C20: Garbage (compulsory charge)
A21: ='SARI YERLERI DOLDUR'!E12 -> 22.98 | B21: =A21/B15 -> 19.499446 | C21: Oto service
A22: ='SARI YERLERI DOLDUR'!C19 -> 106.96659 | B22: =A22/B15 -> 90.76542 | C22: Harbour Master dues
A23: ='SARI YERLERI DOLDUR'!B16 -> 496.06259 | B23: =A23/B15 -> 420.92888 | C23: Sanitary dues
A24: ='SARI YERLERI DOLDUR'!B37 -> 224.03082 | B24: =A24/B15 -> 190.09909 | C24: Light dues
A25: ='SARI YERLERI DOLDUR'!B22 -> 688.91628 | B25: =A25/B15 -> 584.57293 | C25: Customs Overtime
A26: ='SARI YERLERI DOLDUR'!B15 -> 0 | B26: =A26/B15 -> 0 | C26: Anchorage dues for (5)
A27: ='SARI YERLERI DOLDUR'!B28 -> 46.740969 | B27: =A27/B15 -> 39.661576 | C27: Chamber of shipping fee
A28: ='SARI YERLERI DOLDUR'!B29 -> 580 | B28: =A28/B15 -> 492.15313 | C28: Chamber of shipping share on freight
A29: ='SARI YERLERI DOLDUR'!B42 -> 23.587499 | B29: =A29/B15 -> 20.014934 | C29: Contr. to Maritime Association fee
A30: ='SARI YERLERI DOLDUR'!B44 -> 500 | B30: =A30/B15 -> 424.26994 | C30: Motorboat exp.
A31: ='SARI YERLERI DOLDUR'!B45 -> 550 | B31: =A31/B15 -> 466.69693 | C31: Facilities & Other exp.
A32: ='SARI YERLERI DOLDUR'!B46 -> 500 | B32: =A32/B15 -> 424.26994 | C32: Transportation exp.
A33: ='SARI YERLERI DOLDUR'!B47 -> 250 | B33: =A33/B15 -> 212.13497 | C33: Fiscal & Notary exp.
A34: ='SARI YERLERI DOLDUR'!B48 -> 250 | B34: =A34/B15 -> 212.13497 | C34: Communication & Copy & Stamp exp.
A35: ='SARI YERLERI DOLDUR'!B50 -> 530.49952 | B35: =A35/B15 -> 450.15 | C35: Supervision fee (as per official tariff)
A36: ='SARI YERLERI DOLDUR'!B52 -> 1767.7425 | B36: =A36/B15 -> 1500 | C36: Agency fee (as per official tariff, please see below remark)
A37: =SUM(A16:A36) -> 9447.8161 | B37: =SUM(B16:B36) -> 8016.8487 | C37: Total port expenses.
A39: E. & O.E. - All items are subject to final verification against official tariffs.
A40: "Please remit the total amount to our bank account prior to vessel's arrival."
A41: * Turkish Freight Tax: - Nil- Not applicable for discharging cargoes...
A42: * The above basic agency fee is charged for vsl stay in port and/or territorial waters up to 7(seven) days (incl.) irrespective of reason of stay.
A43: When the vsl stay exceeds 7(seven) days, %20 (twenty) of basic fee will be added for each of 5(five) day.
A45: Our Bankers
A46: YAPI KREDI BANKASI
A47: SAIRESREF BRANCH – IZMIR/TURKEY
A48: SWIFT CODE | B48: : YAPITRISXXX
...

Sheet TEKIRDAG CEYPORT
B1: ="PROFORMA D/A – INVOICE (Ref: " & 'GİRİŞ'!C20 & " - " & 'GİRİŞ'!C4 & " Call at " & 'GİRİŞ'!C26 & ")" -> PROFORMA D/A – INVOICE (Ref: 2026/1202 - M/T ALSU Call at IZMIR)
A4: ="TO: " & 'GİRİŞ'!C22 -> TO: CHEMTANKERS SHIPPING SA
A5: ="DATE: " & TEXT('SARI YERLERI DOLDUR'!B1, "dd.mm.yyyy") -> DATE: 24.02.2026
A8: Vessel's Particulars | E8: Port: | F8: TEKIRDAG
A9: Name Of Vsl: | B9: ='SARI YERLERI DOLDUR'!B7 -> M/T ALSU | E9: Purpose Of Call: | F9: ='SARI YERLERI DOLDUR'!E8 -> Discharging
A10: Flag : | B10: ='SARI YERLERI DOLDUR'!E2 -> TURKIYE | E10: Kind Of Cargo: | F10: ='SARI YERLERI DOLDUR'!E9 -> SFS OIL
A11: Nrt: | B11: ='SARI YERLERI DOLDUR'!B8 -> 1004 | E11: Qnty Of Cargo: | F11: ='SARI YERLERI DOLDUR'!B10 -> 3001
A12: Grt: | B12: ='SARI YERLERI DOLDUR'!B9 -> 2298 | E12: Est. Berth Stay: | F12: ='SARI YERLERI DOLDUR'!B11 -> 4
A15: $ 1 = | B15: ='SARI YERLERI DOLDUR'!B6 -> 1.178495 | C15: CEYPORT port in Turkey in/out exp.(estimated)
A16: ='SARI YERLERI DOLDUR'!B24 -> 958.386 | B16: =A16/B15 -> 813.22874 | C16: Pilotage (%50 overtime will applicable on National/ Religions holidays & sundays)
A17: ='SARI YERLERI DOLDUR'!B25 -> 1369.498 | B17: =A17/B15 -> 1162.0737 | C17: Tugboats (%50 overtime will applicable on National/ Religions holidays & sundays)
A18: ='SARI YERLERI DOLDUR'!B32 -> 300 | B18: =A18/B15 -> 254.56196 | C18: Wharfage / Quay dues
A19: ='SARI YERLERI DOLDUR'!B26 -> 117.416 | B19: =A19/B15 -> 99.632158 | C19: Mooring boat (%50 overtime will applicable on National/ Religions holidays & sundays)
A20: ='SARI YERLERI DOLDUR'!B14 -> 164.9893 | B20: =A20/B15 -> 140 | C20: Garbage (compulsory charge)
A21: ='SARI YERLERI DOLDUR'!C19 -> 106.96659 | B21: =A21/B15 -> 90.76542 | C21: Harbour Master dues
A22: ='SARI YERLERI DOLDUR'!B16 -> 496.06259 | B22: =A22/B15 -> 420.92888 | C22: Sanitary dues
A23: ='SARI YERLERI DOLDUR'!B37 -> 224.03082 | B23: =A23/B15 -> 190.09909 | C23: Light dues
A24: ='SARI YERLERI DOLDUR'!B22 -> 688.91628 | B24: =A24/B15 -> 584.57293 | C24: Customs Overtime
A25: ='SARI YERLERI DOLDUR'!B15 -> 0 | B25: =A25/B15 -> 0 | C25: ="Anchorage dues for (" & 'SARI YERLERI DOLDUR'!B13 & ")" -> Anchorage dues for ()
A26: ='SARI YERLERI DOLDUR'!B28 -> 46.740969 | B26: =A26/B15 -> 39.661576 | C26: Chamber of shipping fee
A27: ='SARI YERLERI DOLDUR'!B29 -> 580 | B27: =A27/B15 -> 492.15313 | C27: Chamber of shipping share on freight
A28: ='SARI YERLERI DOLDUR'!B42 -> 23.587499 | B28: =A28/B15 -> 20.014934 | C28: Contr. to Maritime Association fee
A29: ='SARI YERLERI DOLDUR'!B44 -> 500 | B29: =A29/B15 -> 424.26994 | C29: Motorboat exp.
A30: ='SARI YERLERI DOLDUR'!B45 -> 550 | B30: =A30/B15 -> 466.69693 | C30: Facilities & Other exp.
A31: ='SARI YERLERI DOLDUR'!B46 -> 500 | B31: =A31/B15 -> 424.26994 | C31: Transportation exp.
A32: ='SARI YERLERI DOLDUR'!B47 -> 250 | B32: =A32/B15 -> 212.13497 | C32: Fiscal & Notary exp.
A33: ='SARI YERLERI DOLDUR'!B48 -> 250 | B33: =A33/B15 -> 212.13497 | C33: Communication & Copy & Stamp exp.
A34: ='SARI YERLERI DOLDUR'!B50 -> 530.49952 | B34: =A34/B15 -> 450.15 | C34: Supervision fee (as per official tariff)
A35: ='SARI YERLERI DOLDUR'!B52 -> 1767.7425 | B35: =A35/B15 -> 1500 | C35: Agency fee (as per official tariff, please see below remark)
A36: =SUM(A16:A35) -> 9424.8361 | B36: =SUM(B16:B35) -> 7997.3492 | C36: Total port expenses.
A38: E. & O.E. - All items are subject to final verification against official tariffs.
A39: "Please remit the total amount to our bank account prior to vessel's arrival."
A40: * Turkish Freight Tax: - Nil- Not applicable for discharging cargoes...
A41: * The above basic agency fee is charged for vsl stay in port and/or territorial waters up to 7(seven) days (incl.) irrespective of reason of stay.
A42: When the vsl stay exceeds 7(seven) days, %20 (twenty) of basic fee will be added for each of 5(five) day.
A44: Our Bankers
A45: YAPI KREDI BANKASI
A46: SAIRESREF BRANCH – IZMIR/TURKEY
A47: SWIFT CODE | B47: : YAPITRISXXX
A48: USD IBAN | B48: : TR80 0006 7010 0000 0070 3050 34
...

Sheet ISS PALM FORMAT
B1: ="PROFORMA D/A – INVOICE (Ref: " & 'GİRİŞ'!C20 & " - " & 'GİRİŞ'!C4 & " Call at " & 'GİRİŞ'!C26 & ")" -> PROFORMA D/A – INVOICE (Ref: 2026/1202 - M/T ALSU Call at IZMIR)
A4: ="TO: " & 'GİRİŞ'!C22 -> TO: CHEMTANKERS SHIPPING SA
A5: ="DATE: " & TEXT('SARI YERLERI DOLDUR'!B1, "dd.mm.yyyy") -> DATE: 24.02.2026
A8: Vessel's Particulars | E8: Port: | F8: IZMIR
A9: Name Of Vsl: | B9: ='SARI YERLERI DOLDUR'!B7 -> M/T ALSU | E9: Purpose Of Call: | F9: ='SARI YERLERI DOLDUR'!E8 -> Discharging
A10: Flag : | B10: ='SARI YERLERI DOLDUR'!E2 -> TURKIYE | E10: Kind Of Cargo: | F10: ='SARI YERLERI DOLDUR'!E9 -> SFS OIL
A11: Nrt: | B11: ='SARI YERLERI DOLDUR'!B8 -> 1004 | E11: Qnty Of Cargo: | F11: ='SARI YERLERI DOLDUR'!B10 -> 3001
A12: Grt: | B12: ='SARI YERLERI DOLDUR'!B9 -> 2298 | E12: Est. Berth Stay: | F12: ='SARI YERLERI DOLDUR'!B11 -> 4
A15: $ 1 = | B15: ='SARI YERLERI DOLDUR'!B6 -> 1.178495 | C15: Alsancak TCDD port in Turkey in/out exp.(estimated)
A16: ='SARI YERLERI DOLDUR'!B24 -> 958.386 | B16: =A16/B15 -> 813.22874 | C16: Pilotage (%50 overtime will applicable on National/ Religions holidays & sundays)
A17: ='SARI YERLERI DOLDUR'!B25 -> 1369.498 | B17: =A17/B15 -> 1162.0737 | C17: Tugboats (%50 overtime will applicable on National/ Religions holidays & sundays)
A18: ='SARI YERLERI DOLDUR'!B24 -> 958.386 | B18: =A18/B15 -> 813.22874 | C18: Pelikan Bank Passage Pilot(Not Compulsary)
A19: ='SARI YERLERI DOLDUR'!B32 -> 300 | B19: =A19/B15 -> 254.56196 | C19: Wharfage / Quay dues
A20: ='SARI YERLERI DOLDUR'!B26 -> 117.416 | B20: =A20/B15 -> 99.632158 | C20: Mooring boat (%50 overtime will applicable on National/ Religions holidays & sundays)
A21: ='SARI YERLERI DOLDUR'!B14 -> 164.9893 | B21: =A21/B15 -> 140 | C21: Garbage (compulsory charge)
A22: ='SARI YERLERI DOLDUR'!C19 -> 106.96659 | B22: =A22/B15 -> 90.76542 | C22: Harbour Master dues
A23: ='SARI YERLERI DOLDUR'!B16 -> 496.06259 | B23: =A23/B15 -> 420.92888 | C23: Sanitary dues
A24: ='SARI YERLERI DOLDUR'!B37 -> 224.03082 | B24: =A24/B15 -> 190.09909 | C24: Light dues
A25: ='SARI YERLERI DOLDUR'!B40 -> 46.2 | B25: =A25/B15 -> 39.202542 | C25: Vts Fee
A26: ='SARI YERLERI DOLDUR'!B22 -> 688.91628 | B26: =A26/B15 -> 584.57293 | C26: Customs Overtime
A27: ='SARI YERLERI DOLDUR'!B28 -> 46.740969 | B27: =A27/B15 -> 39.661576 | C27: Chamber of shipping fee
A28: ='SARI YERLERI DOLDUR'!B29 -> 580 | B28: =A28/B15 -> 492.15313 | C28: Chamber of shipping share on freight
A29: ='SARI YERLERI DOLDUR'!J3 -> 225 | B29: =A29/B15 -> 190.92147 | C29: Motorboat exp.
A30: ='SARI YERLERI DOLDUR'!J5 -> 2400 | B30: =A30/B15 -> 2036.4957 | C30: Agency fee (as per official tariff, please see below remark)
A31: =SUM(A16:A30) -> 8682.5926 | B31: =SUM(B16:B30) -> 7367.526 | C31: Total port expenses.
A33: E. & O.E. - All items are subject to final verification against official tariffs.
A34: "Please remit the total amount to our bank account prior to vessel's arrival."
A35: * Turkish Freight Tax: - Nil- Not applicable for discharging cargoes...
A36: * The above basic agency fee is charged for vsl stay in port and/or territorial waters up to 7(seven) days (incl.) irrespective of reason of stay.
A37: When the vsl stay exceeds 7(seven) days, %20 (twenty) of basic fee will be added for each of 5(five) day.
A39: Our Bankers
A40: YAPI KREDI BANKASI
A41: SAIRESREF BRANCH – IZMIR/TURKEY
A42: SWIFT CODE | B42: : YAPITRISXXX
A43: USD IBAN | B43: : TR80 0006 7010 0000 0070 3050 34
A44: EUR IBAN | B44: : TR89 0006 7010 0000 0059 7528 24
A45: TL IBAN | B45: : TR47 0006 7010 0000 0070 2494 65
A46: IN FAVOUR OF | B46: : SELIM DENIZCILIK,NAKLIYAT,GEMICILIK SAN.TIC.LTD.STI.
A49: Alsancak, Kıbrıs Sehitleri Cd. No: 148 K:5 D: 503, 35220 Konak/Izmir - TURKIYE | T. Office: KORDON - T. No:7600137148 TEL: +90 232 464 47 11 | www.selimshipping.com
A50: HQ: IZMIR | BRANCHES: ALIAGA - TEKIRDAG - MERSIN

Sheet TCDD IZMIR 
B1: ="PROFORMA D/A – INVOICE (Ref: " & 'GİRİŞ'!C20 & " - " & 'GİRİŞ'!C4 & " Call at " & 'GİRİŞ'!C26 & ")" -> PROFORMA D/A – INVOICE (Ref: 2026/1202 - M/T ALSU Call at IZMIR)
A4: ="TO: " & 'GİRİŞ'!C22 -> TO: CHEMTANKERS SHIPPING SA
A5: ="DATE: " & TEXT('SARI YERLERI DOLDUR'!B1, "dd.mm.yyyy") -> DATE: 24.02.2026
A8: Vessel's Particulars | E8: Port: | F8: IZMIR
A9: Name Of Vsl: | B9: ='SARI YERLERI DOLDUR'!B7 -> M/T ALSU | E9: Purpose Of Call: | F9: ='SARI YERLERI DOLDUR'!E8 -> Discharging
A10: Flag : | B10: ='SARI YERLERI DOLDUR'!E2 -> TURKIYE | E10: Kind Of Cargo: | F10: ='SARI YERLERI DOLDUR'!E9 -> SFS OIL
A11: Nrt: | B11: ='SARI YERLERI DOLDUR'!B8 -> 1004 | E11: Qnty Of Cargo: | F11: ='SARI YERLERI DOLDUR'!B10 -> 3001
A12: Grt: | B12: ='SARI YERLERI DOLDUR'!B9 -> 2298 | E12: Est. Berth Stay: | F12: ='SARI YERLERI DOLDUR'!B11 -> 4
A15: $ 1 = | B15: ='SARI YERLERI DOLDUR'!B6 -> 1.178495 | C15: Alsancak TCDD port in Turkey in/out exp.(estimated)
A16: ='SARI YERLERI DOLDUR'!B24 -> 958.386 | B16: =A16/B15 -> 813.22874 | C16: Pilotage (%50 overtime will applicable on National/ Religions holidays & sundays)
A17: ='SARI YERLERI DOLDUR'!B25 -> 1369.498 | B17: =A17/B15 -> 1162.0737 | C17: Tugboats (%50 overtime will applicable on National/ Religions holidays & sundays)
A18: ='SARI YERLERI DOLDUR'!B32 -> 300 | B18: =A18/B15 -> 254.56196 | C18: Wharfage / Quay dues
A19: ='SARI YERLERI DOLDUR'!B26 -> 117.416 | B19: =A19/B15 -> 99.632158 | C19: Mooring boat (%50 overtime will applicable on National/ Religions holidays & sundays)
A20: ='SARI YERLERI DOLDUR'!B14 -> 164.9893 | B20: =A20/B15 -> 140 | C20: Garbage (compulsory charge)
A21: ='SARI YERLERI DOLDUR'!C19 -> 106.96659 | B21: =A21/B15 -> 90.76542 | C21: Harbour Master dues
A22: ='SARI YERLERI DOLDUR'!B16 -> 496.06259 | B22: =A22/B15 -> 420.92888 | C22: Sanitary dues
A23: ='SARI YERLERI DOLDUR'!B37 -> 224.03082 | B23: =A23/B15 -> 190.09909 | C23: Light dues
A24: ='SARI YERLERI DOLDUR'!B22 -> 688.91628 | B24: =A24/B15 -> 584.57293 | C24: Customs Overtime
A25: ='SARI YERLERI DOLDUR'!B15 -> 0 | B25: =A25/B15 -> 0 | C25: Anchorage dues
A26: ='SARI YERLERI DOLDUR'!B28 -> 46.740969 | B26: =A26/B15 -> 39.661576 | C26: Chamber of shipping fee
A27: ='SARI YERLERI DOLDUR'!B29 -> 580 | B27: =A27/B15 -> 492.15313 | C27: Chamber of shipping share on freight
A28: ='SARI YERLERI DOLDUR'!B44 -> 500 | B28: =A28/B15 -> 424.26994 | C28: Motorboat exp.
A29: ='SARI YERLERI DOLDUR'!B45 -> 550 | B29: =A29/B15 -> 466.69693 | C29: Facilities & Other exp.
A30: ='SARI YERLERI DOLDUR'!B46 -> 500 | B30: =A30/B15 -> 424.26994 | C30: Transportation exp.
A31: ='SARI YERLERI DOLDUR'!B47 -> 250 | B31: =A31/B15 -> 212.13497 | C31: Fiscal & Notary exp.
A32: ='SARI YERLERI DOLDUR'!B48 -> 250 | B32: =A32/B15 -> 212.13497 | C32: Communication & Copy & Stamp exp.
A33: ='SARI YERLERI DOLDUR'!B50 -> 530.49952 | B33: =A33/B15 -> 450.15 | C33: Supervision fee (as per official tariff)
A34: ='SARI YERLERI DOLDUR'!B52 -> 1767.7425 | B34: =A34/B15 -> 1500 | C34: Agency fee (as per official tariff, please see below remark)
A35: =SUM(A16:A34) -> 9401.2486 | B35: =SUM(B16:B34) -> 7977.3343 | C35: Total port expenses.
A37: E. & O.E. - All items are subject to final verification against official tariffs.
A38: "Please remit the total amount to our bank account prior to vessel's arrival."
A39: * Turkish Freight Tax: - Nil- Not applicable for discharging cargoes...
A40: * The above basic agency fee is charged for vsl stay in port and/or territorial waters up to 7(seven) days (incl.) irrespective of reason of stay.
A41: When the vsl stay exceeds 7(seven) days, %20 (twenty) of basic fee will be added for each of 5(five) day.
A43: Our Bankers
A44: YAPI KREDI BANKASI
A45: SAIRESREF BRANCH – IZMIR/TURKEY
A46: SWIFT CODE | B46: : YAPITRISXXX
A47: USD IBAN | B47: : TR80 0006 7010 0000 0070 3050 34
A48: EUR IBAN | B48: : TR89 0006 7010 0000 0059 7528 24
...

Sheet SARI YERLERI DOLDUR
A1: Tarih | B1: =TODAY() -> 46077 | D1: LİMAN | E1: TEKIRDAG | I1: ISS PALM TARIFE | M1: M (Başlangıç Tonajı) | N1: N (Fiyat TL) | P1: P (Hizmet) | Q1: Q (Taban $) | R1: R (Ek 1000 GRT $) | S1: S (Başlangıç NRT) | T1: T (Mesai Dışı Ücret TL) | V1: V (Başlangıç) | W1: W (İthalat TL) | X1: X (İhracat TL) | Z1: AE (Başlangıç NT) | AA1: AF (Yabancı $) | AB1: AG (Türk $) | AC1: AH (Kabotaj $)
A2: USD Kuru (Otomatik) | B2: =IFERROR(__xludf.DUMMYFUNCTION("GOOGLEFINANCE(""CURRENCY:USDTRY"")"),43.858740000000004) -> 43.85874 | D2: BAYRAK | E2: ='GİRİŞ'!C23 -> TURKIYE | M2: 0 | N2: 1283.9 | P2: Kılavuzluk | Q2: 202.27 | R2: 83.17 | S2: 0 | T2: 251 | V2: 0 | W2: 20100 | X2: 8615 | Z2: 0 | AA2: 0 | AB2: 0 | AC2: 0
A3: EUR KURU (Otomatik) | B3: =IFERROR(__xludf.DUMMYFUNCTION("GOOGLEFINANCE(""CURRENCY:EURTRY"")"),51.7259) -> 51.7259 | I3: MOTORBOAT | J3: 225 | M3: 501 | N3: 3424 | P3: Römorkör | Q3: 382.99 | R3: 71.87 | S3: 501 | T3: 628 | V3: 3001 | W3: 26350 | X3: 11230 | Z3: 300 | AA3: 92.4 | AB3: 23.1 | AC3: 8.4
M4: 2001 | N4: 6848.1 | S4: 2001 | T4: 1506 | V4: 6001 | W4: 32700 | X4: 13750 | Z4: 2001 | AA4: 184.8 | AB4: 46.2 | AC4: 16.8
I5: AGENCY FEE | J5: 2400 | M5: 4001 | N5: 10272.2 | S5: 4001 | T5: 2259 | V5: 9001 | W5: 38840 | X5: 16465 | Z5: 5001 | AA5: 346.5 | AB5: 86.625 | AC5: 31.5
A6: PARİTE EUR/USD (Otomatik) | B6: =IFERROR(__xludf.DUMMYFUNCTION("GOOGLEFINANCE(""CURRENCY:EURUSD"")"),1.1784949999999998) -> 1.178495 | M6: 8001 | N6: 17120.2 | S6: 8001 | T6: 3012 | V6: 12001 | W6: 45305 | X6: 18505 | Z6: 10001 | AA6: 519.75 | AB6: 129.9375 | AC6: 47.25
A7: GEMİ ADI | B7: ='GİRİŞ'!C4 -> M/T ALSU | M7: 10001 | N7: 34240.9 | P7: Palamar | Q7: 22.58 | R7: 11.29 | S7: 10001 | T7: 6024 | V7: 15001 | W7: 51585 | X7: 21345 | Z7: 20001 | AA7: 693 | AB7: 173.25 | AC7: 63
A8: NRT (Net Tonaj) | B8: ='GİRİŞ'!C5 -> 1004 | D8: Geliș nedeni | E8: ='GİRİŞ'!C24 -> Discharging | M8: 30001 | N8: 51361.4 | S8: 30001 | T8: 9036 | V8: 18001 | W8: 57935 | X8: 24915 | Z8: 50001 | AA8: 1039.5 | AB8: 259.875 | AC8: 94.5
A9: GRT (Gross Tonaj) | B9: ='GİRİŞ'!C6 -> 2298 | D9: Kind of Cargo | E9: ='GİRİŞ'!C25 -> SFS OIL | M9: 50001 | N9: 85602.3 | S9: 50001 | T9: 15059 | V9: 21001 | W9: 62210 | X9: 28395 | Z9: VTS ÜCRETİ
A10: Yük Miktarı | B10: ='GİRİŞ'!C7 -> 3001 | S10: MESAİ DIŞI ORDİNO | V10: 25001 | W10: 68525 | X10: 35830
A11: Gemini tahmini barınma günü | B11: ='GİRİŞ'!C8 -> 4 | V11: 30001 | W11: 77205 | X11: 42335
A12: TEHLİKELİ YÜK | B12: ='GİRİŞ'!C10 -> EVET | D12: OTO SERVİS | E12: =(B9 * 0.01) -> 22.98 | V12: 35001 | W12: 106105 | X12: 46770
A13: GEMİNİN DEMIRLE KALMASI BEKLENEN | B13: ='GİRİŞ'!C9
A14: Garbage | B14: {=LOOKUP(B9, {0; 1001; 5001; 10001; 15001; 20001; 25001; 35001; 60001}, {80; 140; 210; 250; 300; 350; 400; 540; 720}) * B6} -> 164.9893
A15: Demirleme Ücreti | B15: =IF(B13=0, 0, IF(B11<=7, B9*0.004*B11, (B9*0.004*7) + (B9*0.006*(B11-7)))) -> 0
A16: Sağlık Resmi ($) | B16: =(B8 * 21.67) / B2 -> 496.06259
A17: TOPLAM KIYI EMNİYETİ ($) | M17: Z (Sadece Sayı) | N17: AA (Türk TL) | O17: AB (Yabancı TL) | Q17: AC (Sadece Sayı) | R17: AD (Fiyat $) | T17: Liman Hizmetleri | U17: kabotaj
A18: LÇB | B18: {=INDEX($N$2:$N$9, MATCH(MIN(ABS($M$2:$M$9 - B8)), ABS($M$2:$M$9 - B8), 0)) / B2} -> 78.068818 | M18: 0 | N18: 670 | O18: 1400 | Q18: 0 | R18: 580
A19: Mesai Dışı LÇB | B19: {=INDEX($T$2:$T$9, MATCH(MIN(ABS($S$2:$S$9 - B8)), ABS($S$2:$S$9 - B8), 0)) / B2} -> 14.318697 | C19: =SUM(B19, B18,2*B20) -> 106.96659 | M19: 501 | N19: 1120 | O19: 2800 | Q19: 20001 | R19: 870 | T19: kılavuzluk | U19: 202.27 | V19: 83.17
A20: ORDİNO | B20: =(B19 / 2) + (5.71 / B2) -> 7.2895391 | M20: 1501 | N20: 2050 | O20: 4200 | Q20: 40001 | R20: 1130 | T20: Römorkör | U20: 382.99 | V20: 71.87
A21: GÜMRÜK SEÇ | M21: 2501 | N21: 2800 | O21: 4900 | Q21: 60001 | R21: 1400 | T21: Palamar | U21: 22.58 | V21: 11.29
A22: ='GİRİŞ'!C11 -> İTHALAT | B22: =IFERROR(__xludf.DUMMYFUNCTION("IF(ISNUMBER(SEARCH(""TEK"", A22)), 7900 / B2, IF(ISNUMBER(SEARCH(""ALİAĞA"", A22)), 214.1960779, IF(B10="""", 0, VLOOKUP(B10, V:X, IF(TRIM(A22)=""İTHALAT"", 2, 3), TRUE) / B2))) + IF(OR(A22=""İTHALAT"", A22=""İHRACAT""), 3865 / GOOGLEFINANCE(""CURRENCY:US"&"DTRY""), 0)"),688.9162798566489) -> 688.91628 | M22: 5001 | N22: 3400 | O22: 5600 | Q22: 100001 | R22: 1780
A23: KILAVUZLUK | M23: 10001 | N23: 4000 | O23: 6300
A24: Kabotaj hattı | B24: =2 * IF(B9<=1000, $Q$2, $Q$2 + (ROUNDUP((B9-1000)/1000, 0) * $R$2))* IF(TRIM($B$12)="EVET", 1.3, 1) -> 958.386 | M24: 25001 | N24: 4500 | O24: 7000
A25: Römorkör Ücreti (Towage) | B25: =IF(B9>5000, 4, 2) * IF(B9<=1000, $Q$3, $Q$3 + (ROUNDUP((B9-1000)/1000, 0) * $R$3))* IF(TRIM($B$12)="EVET", 1.3, 1) -> 1369.498 | M25: 35001 | N25: 5000 | O25: 7500
A26: Palamar (Mooring) | B26: =2 * IF(B9<=1000, $Q$7, $Q$7 + (ROUNDUP((B9-1000)/1000,0) * $R$7))* IF(TRIM($B$12)="EVET", 1.3, 1) -> 117.416 | M26: 50001 | N26: 5300 | O26: 8000
A28: ='GİRİŞ'!C13 -> TÜRK / CHAMBER OF SHIPPING FEE | B28: =IF(LEFT(TRIM(A28), 1)="T", VLOOKUP(B9, $M$17:$O$26, 2, TRUE), VLOOKUP(B9, $M$17:$O$26, 3, TRUE)) / B2 -> 46.740969
A29: DTO HASILATI ODA PAYI | B29: =IF(B10="", 0, VLOOKUP(B10, $Q$17:$R$22, 2, TRUE)) -> 580
M30: ACENTELİK ÜCRETİ
A31: BARINMA GENEL LİMANLAR | M31: AK (NRT Başlangıç) | N31: AL (Taban Fiyat €) | O31: AM (Ek Artış €)
A32: ='GİRİŞ'!C14 -> YABANCI | B32: =IF(A32="İZMİR/TCDD", ROUNDUP(B9/1000, 0) * B11 * 10,ROUNDUP(IF(B9<=500, 10, ROUNDUP(B9/1000, 0) * 25) * IF(ISNUMBER(SEARCH("YABANCI", A32)), 1, IF(ISNUMBER(SEARCH("KABOTAJ", A32)), 0.5, 0.75)), 0) * B11) -> 300 | M32: 0 | N32: 600 | O32: 0
M33: 501 | N33: 1000 | O33: 0
A34: OTO SERVİS | M34: 1001 | N34: 1500 | O34: 0
M35: 2001 | N35: 1850 | O35: 0
A36: FENER | M36: 3001 | N36: 2300 | O36: 0
A37: ='GİRİŞ'!C16 -> TÜRK | B37: =IF(ISNUMBER(SEARCH("YABANCI", A37)), (MIN(B8,800)*0.22176 + MAX(0,B8-800)*0.11088), IF(ISNUMBER(SEARCH("KABOTAJ", A37)), (MIN(B8,800)*0.03528 + MAX(0,B8-800)*0.01764), (MIN(B8,800)*0.1241856 + MAX(0,B8-800)*0.0620928))) * 2 -> 224.03082 | M37: 4001 | N37: 2750 | O37: 0
M38: 5001 | N38: 3200 | O38: 0
A39: VTS | M39: 7501 | N39: 4000 | O39: 0
A40: ='GİRİŞ'!C18 -> TÜRK | B40: =IF(B8<300, 0, VLOOKUP(B8, $Z$1:$AC$8, IF(ISNUMBER(SEARCH("KABOTAJ", A40)), 4, IF(ISNUMBER(SEARCH("YABANCI", A40)), 2, 3)), TRUE)) * 2 -> 46.2 | M40: 10001 | N40: 4000 | O40: 75
M41: 20001 | N41: 4750 | O41: 65
...
